Traceback (most recent call last):
  File "/home/pedrohlopes/miniconda3/envs/dev_pedro/lib/python3.7/site-packages/jupyter_cache/executors/utils.py", line 64, in single_nb_execution
    **kwargs,
  File "/home/pedrohlopes/miniconda3/envs/dev_pedro/lib/python3.7/site-packages/nbclient/client.py", line 1112, in execute
    return NotebookClient(nb=nb, resources=resources, km=km, **kwargs).execute()
  File "/home/pedrohlopes/miniconda3/envs/dev_pedro/lib/python3.7/site-packages/nbclient/util.py", line 74, in wrapped
    return just_run(coro(*args, **kwargs))
  File "/home/pedrohlopes/miniconda3/envs/dev_pedro/lib/python3.7/site-packages/nbclient/util.py", line 53, in just_run
    return loop.run_until_complete(coro)
  File "/home/pedrohlopes/miniconda3/envs/dev_pedro/lib/python3.7/asyncio/base_events.py", line 587, in run_until_complete
    return future.result()
  File "/home/pedrohlopes/miniconda3/envs/dev_pedro/lib/python3.7/site-packages/nbclient/client.py", line 554, in async_execute
    cell, index, execution_count=self.code_cells_executed + 1
  File "/home/pedrohlopes/miniconda3/envs/dev_pedro/lib/python3.7/site-packages/nbclient/client.py", line 857, in async_execute_cell
    self._check_raise_for_error(cell, exec_reply)
  File "/home/pedrohlopes/miniconda3/envs/dev_pedro/lib/python3.7/site-packages/nbclient/client.py", line 760, in _check_raise_for_error
    raise CellExecutionError.from_cell_and_msg(cell, exec_reply_content)
nbclient.exceptions.CellExecutionError: An error occurred while executing the following cell:
------------------
start = 10
end = 15

S = np.abs(stft(data[start*samplerate:end*samplerate]))
fig, ax = plt.subplots()
img = librosa.display.specshow(librosa.amplitude_to_db(S,
                                                       ref=np.max),
                               y_axis='linear', x_axis='time', ax=ax)
ax.set_title('Power spectrogram')
fig.colorbar(img, ax=ax, format="%+2.0f dB")
------------------

[0;31m---------------------------------------------------------------------------[0m
[0;31mTypeError[0m                                 Traceback (most recent call last)
[0;32m/tmp/ipykernel_286/2839169386.py[0m in [0;36m<module>[0;34m[0m
[1;32m      6[0m img = librosa.display.specshow(librosa.amplitude_to_db(S,
[1;32m      7[0m                                                        ref=np.max),
[0;32m----> 8[0;31m                                y_axis='linear', x_axis='time', ax=ax)
[0m[1;32m      9[0m [0max[0m[0;34m.[0m[0mset_title[0m[0;34m([0m[0;34m'Power spectrogram'[0m[0;34m)[0m[0;34m[0m[0;34m[0m[0m
[1;32m     10[0m [0mfig[0m[0;34m.[0m[0mcolorbar[0m[0;34m([0m[0mimg[0m[0;34m,[0m [0max[0m[0;34m=[0m[0max[0m[0;34m,[0m [0mformat[0m[0;34m=[0m[0;34m"%+2.0f dB"[0m[0;34m)[0m[0;34m[0m[0;34m[0m[0m

[0;32m~/miniconda3/envs/dev_pedro/lib/python3.7/site-packages/librosa/display.py[0m in [0;36mspecshow[0;34m(data, x_coords, y_coords, x_axis, y_axis, sr, hop_length, fmin, fmax, bins_per_octave, **kwargs)[0m
[1;32m    676[0m [0;34m[0m[0m
[1;32m    677[0m     [0maxes[0m [0;34m=[0m [0mplt[0m[0;34m.[0m[0mgca[0m[0;34m([0m[0;34m)[0m[0;34m[0m[0;34m[0m[0m
[0;32m--> 678[0;31m     [0mout[0m [0;34m=[0m [0maxes[0m[0;34m.[0m[0mpcolormesh[0m[0;34m([0m[0mx_coords[0m[0;34m,[0m [0my_coords[0m[0;34m,[0m [0mdata[0m[0;34m,[0m [0;34m**[0m[0mkwargs[0m[0;34m)[0m[0;34m[0m[0;34m[0m[0m
[0m[1;32m    679[0m     [0mplt[0m[0;34m.[0m[0msci[0m[0;34m([0m[0mout[0m[0;34m)[0m[0;34m[0m[0;34m[0m[0m
[1;32m    680[0m [0;34m[0m[0m

[0;31mTypeError[0m: inner() got multiple values for argument 'ax'
TypeError: inner() got multiple values for argument 'ax'

